Started by user [8mha:////4MLFtQFmIT7BWDPipzoY3HxXD1yuMMRRYvRP7P9s7sBVAAAAlx+LCAAAAAAAAP9b85aBtbiIQTGjNKU4P08vOT+vOD8nVc83PyU1x6OyILUoJzMv2y+/JJUBAhiZGBgqihhk0NSjKDWzXb3RdlLBUSYGJk8GtpzUvPSSDB8G5tKinBIGIZ+sxLJE/ZzEvHT94JKizLx0a6BxUmjGOUNodHsLgAzmEgYe/dLi1CL9DKCdmSUAHtX1jcEAAAA=[0mMKI
Running as SYSTEM
Building in workspace /var/jenkins_home/workspace/ansible-test
[Checks API] No suitable checks publisher found.
[ansible-test] $ ansible-playbook /var/jenkins_home/ansible/play.yml -i /var/jenkins_home/ansible/hosts -f 5
/usr/local/lib/python3.5/dist-packages/ansible/parsing/vault/__init__.py:44: CryptographyDeprecationWarning: Python 3.5 support will be dropped in the next release ofcryptography. Please upgrade your Python.
  from cryptography.exceptions import InvalidSignature

PLAY [test1] *******************************************************************

TASK [Gathering Facts] *********************************************************
ok: [test1]

TASK [debug] *******************************************************************
fatal: [test1]: FAILED! => {"msg": "The task includes an option with an undefined variable. The error was: 'MSG' is undefined\n\nThe error appears to be in '/var/jenkins_home/ansible/play.yml': line 3, column 6, but may\nbe elsewhere in the file depending on the exact syntax problem.\n\nThe offending line appears to be:\n\n  tasks:\n   - debug:\n     ^ here\n"}

PLAY RECAP *********************************************************************
test1                      : ok=1    changed=0    unreachable=0    failed=1    skipped=0    rescued=0    ignored=0   

Exception ignored in: <function WeakValueDictionary.__init__.<locals>.remove at 0x7fc643ee79d8>
Traceback (most recent call last):
  File "/usr/lib/python3.5/weakref.py", line 117, in remove
TypeError: 'NoneType' object is not callable
Exception ignored in: <function WeakValueDictionary.__init__.<locals>.remove at 0x7fc643ee79d8>
Traceback (most recent call last):
  File "/usr/lib/python3.5/weakref.py", line 117, in remove
TypeError: 'NoneType' object is not callable
Exception ignored in: <function WeakValueDictionary.__init__.<locals>.remove at 0x7fc643ee79d8>
Traceback (most recent call last):
  File "/usr/lib/python3.5/weakref.py", line 117, in remove
TypeError: 'NoneType' object is not callable
Exception ignored in: <function WeakValueDictionary.__init__.<locals>.remove at 0x7fc643ee79d8>
Traceback (most recent call last):
  File "/usr/lib/python3.5/weakref.py", line 117, in remove
TypeError: 'NoneType' object is not callable
Exception ignored in: <function WeakValueDictionary.__init__.<locals>.remove at 0x7fc643ee79d8>
Traceback (most recent call last):
  File "/usr/lib/python3.5/weakref.py", line 117, in remove
TypeError: 'NoneType' object is not callable
Exception ignored in: <function WeakValueDictionary.__init__.<locals>.remove at 0x7fc643ee79d8>
Traceback (most recent call last):
  File "/usr/lib/python3.5/weakref.py", line 117, in remove
TypeError: 'NoneType' object is not callable
Exception ignored in: <function WeakValueDictionary.__init__.<locals>.remove at 0x7fc643ee79d8>
Traceback (most recent call last):
  File "/usr/lib/python3.5/weakref.py", line 117, in remove
TypeError: 'NoneType' object is not callable
Exception ignored in: <function WeakValueDictionary.__init__.<locals>.remove at 0x7fc643ee79d8>
Traceback (most recent call last):
  File "/usr/lib/python3.5/weakref.py", line 117, in remove
TypeError: 'NoneType' object is not callable
Exception ignored in: <function WeakValueDictionary.__init__.<locals>.remove at 0x7fc643ee79d8>
Traceback (most recent call last):
  File "/usr/lib/python3.5/weakref.py", line 117, in remove
TypeError: 'NoneType' object is not callable
Exception ignored in: <function WeakValueDictionary.__init__.<locals>.remove at 0x7fc643ee79d8>
Traceback (most recent call last):
  File "/usr/lib/python3.5/weakref.py", line 117, in remove
TypeError: 'NoneType' object is not callable
Exception ignored in: <function WeakValueDictionary.__init__.<locals>.remove at 0x7fc643ee79d8>
Traceback (most recent call last):
  File "/usr/lib/python3.5/weakref.py", line 117, in remove
TypeError: 'NoneType' object is not callable
Exception ignored in: <function WeakValueDictionary.__init__.<locals>.remove at 0x7fc643ee79d8>
Traceback (most recent call last):
  File "/usr/lib/python3.5/weakref.py", line 117, in remove
TypeError: 'NoneType' object is not callable
Exception ignored in: <function WeakValueDictionary.__init__.<locals>.remove at 0x7fc643ee79d8>
Traceback (most recent call last):
  File "/usr/lib/python3.5/weakref.py", line 117, in remove
TypeError: 'NoneType' object is not callable
Exception ignored in: <function WeakValueDictionary.__init__.<locals>.remove at 0x7fc643ee79d8>
Traceback (most recent call last):
  File "/usr/lib/python3.5/weakref.py", line 117, in remove
TypeError: 'NoneType' object is not callable
Exception ignored in: <function WeakValueDictionary.__init__.<locals>.remove at 0x7fc643ee79d8>
Traceback (most recent call last):
  File "/usr/lib/python3.5/weakref.py", line 117, in remove
TypeError: 'NoneType' object is not callable
Exception ignored in: <function WeakValueDictionary.__init__.<locals>.remove at 0x7fc643ee79d8>
Traceback (most recent call last):
  File "/usr/lib/python3.5/weakref.py", line 117, in remove
TypeError: 'NoneType' object is not callable
Exception ignored in: <function WeakValueDictionary.__init__.<locals>.remove at 0x7fc643ee79d8>
Traceback (most recent call last):
  File "/usr/lib/python3.5/weakref.py", line 117, in remove
TypeError: 'NoneType' object is not callable
Exception ignored in: <function WeakValueDictionary.__init__.<locals>.remove at 0x7fc643ee79d8>
Traceback (most recent call last):
  File "/usr/lib/python3.5/weakref.py", line 117, in remove
TypeError: 'NoneType' object is not callable
Exception ignored in: <function WeakValueDictionary.__init__.<locals>.remove at 0x7fc643ee79d8>
Traceback (most recent call last):
  File "/usr/lib/python3.5/weakref.py", line 117, in remove
TypeError: 'NoneType' object is not callable
Exception ignored in: <function WeakValueDictionary.__init__.<locals>.remove at 0x7fc643ee79d8>
Traceback (most recent call last):
  File "/usr/lib/python3.5/weakref.py", line 117, in remove
TypeError: 'NoneType' object is not callable
Exception ignored in: <function WeakValueDictionary.__init__.<locals>.remove at 0x7fc643ee79d8>
Traceback (most recent call last):
  File "/usr/lib/python3.5/weakref.py", line 117, in remove
TypeError: 'NoneType' object is not callable
Exception ignored in: <function WeakValueDictionary.__init__.<locals>.remove at 0x7fc643ee79d8>
Traceback (most recent call last):
  File "/usr/lib/python3.5/weakref.py", line 117, in remove
TypeError: 'NoneType' object is not callable
Exception ignored in: <function WeakValueDictionary.__init__.<locals>.remove at 0x7fc643ee79d8>
Traceback (most recent call last):
  File "/usr/lib/python3.5/weakref.py", line 117, in remove
TypeError: 'NoneType' object is not callable
Exception ignored in: <function WeakValueDictionary.__init__.<locals>.remove at 0x7fc643ee79d8>
Traceback (most recent call last):
  File "/usr/lib/python3.5/weakref.py", line 117, in remove
TypeError: 'NoneType' object is not callable
Exception ignored in: <function WeakValueDictionary.__init__.<locals>.remove at 0x7fc643ee79d8>
Traceback (most recent call last):
  File "/usr/lib/python3.5/weakref.py", line 117, in remove
TypeError: 'NoneType' object is not callable
Exception ignored in: <function WeakValueDictionary.__init__.<locals>.remove at 0x7fc643ee79d8>
Traceback (most recent call last):
  File "/usr/lib/python3.5/weakref.py", line 117, in remove
TypeError: 'NoneType' object is not callable
Exception ignored in: <function WeakValueDictionary.__init__.<locals>.remove at 0x7fc643ee79d8>
Traceback (most recent call last):
  File "/usr/lib/python3.5/weakref.py", line 117, in remove
TypeError: 'NoneType' object is not callable
Exception ignored in: <function WeakValueDictionary.__init__.<locals>.remove at 0x7fc643ee79d8>
Traceback (most recent call last):
  File "/usr/lib/python3.5/weakref.py", line 117, in remove
TypeError: 'NoneType' object is not callable
Exception ignored in: <function WeakValueDictionary.__init__.<locals>.remove at 0x7fc643ee79d8>
Traceback (most recent call last):
  File "/usr/lib/python3.5/weakref.py", line 117, in remove
TypeError: 'NoneType' object is not callable
FATAL: command execution failed
hudson.AbortException: Ansible playbook execution failed
	at org.jenkinsci.plugins.ansible.AnsiblePlaybookBuilder.perform(AnsiblePlaybookBuilder.java:262)
	at org.jenkinsci.plugins.ansible.AnsiblePlaybookBuilder.perform(AnsiblePlaybookBuilder.java:232)
	at jenkins.tasks.SimpleBuildStep.perform(SimpleBuildStep.java:123)
	at hudson.tasks.BuildStepCompatibilityLayer.perform(BuildStepCompatibilityLayer.java:80)
	at hudson.tasks.BuildStepMonitor$1.perform(BuildStepMonitor.java:20)
	at hudson.model.AbstractBuild$AbstractBuildExecution.perform(AbstractBuild.java:804)
	at hudson.model.Build$BuildExecution.build(Build.java:197)
	at hudson.model.Build$BuildExecution.doRun(Build.java:163)
	at hudson.model.AbstractBuild$AbstractBuildExecution.run(AbstractBuild.java:514)
	at hudson.model.Run.execute(Run.java:1907)
	at hudson.model.FreeStyleBuild.run(FreeStyleBuild.java:43)
	at hudson.model.ResourceController.execute(ResourceController.java:97)
	at hudson.model.Executor.run(Executor.java:428)
ERROR: Ansible playbook execution failed
[Checks API] No suitable checks publisher found.
Finished: FAILURE
